<robot name="fr3">
  
  
  
  
  
  
  <link name="base_link">
      </link>
  <joint name="fr3_base_joint" type="fixed">
    <parent link="base_link" />
    <child link="fr3_link0" />
    <origin rpy="0 0 0" xyz="0 0 0" />
  </joint>
  
  <link name="fr3_link0">
    <visual name="fr3_link0_visual">
      <geometry>
        <cylinder radius="0.05" length="0.1" /></geometry>
    </visual>
    <collision name="fr3_link0_collision">
      <geometry>
        <mesh filename="../meshes/fr3/link0.stl" />
      </geometry>
    </collision>
    <inertial>
      <origin rpy="0 0 0" xyz="-0.0172 0.0004 0.0745" />
      <mass value="2.3966" />
      <inertia ixx="0.009" ixy="0.0" ixz="0.002" iyy="0.0115" iyz="0.0" izz="0.0085" />
    </inertial>
  </link>
  
  <link name="fr3_link1">
    <visual name="fr3_link1_visual">
      <geometry>
        <cylinder radius="0.05" length="0.1" /></geometry>
    </visual>
    <collision name="fr3_link1_collision">
      <geometry>
        <mesh filename="../meshes/fr3/link1.stl" />
      </geometry>
    </collision>
    <inertial>
      <origin rpy="0 0 0" xyz="0.0000004128 -0.0181251324 -0.0386035970" />
      <mass value="2.9274653454" />
      <inertia ixx="0.023927316485107913" ixy="1.3317903455714081e-05" ixz="-0.00011404774918616684" iyy="0.0224821613275756" iyz="-0.0019950320628240115" izz="0.006350098258530016" />
    </inertial>
  </link>
  <joint name="fr3_joint1" type="revolute">
    <origin rpy="2.4720264225882587e-18 6.545184717647776e-17 1.0066016825856867e-17" xyz="-2.1551860152410533e-16 3.466379412284068e-18 0.3330000000000001" />
    <parent link="fr3_link0" />
    <child link="fr3_link1" />
    <axis xyz="0 0 1" />
    <limit effort="87.0" lower="-2.7437" upper="2.7437" velocity="2.62" />
    <safety_controller k_position="100.0" k_velocity="40.0" soft_lower_limit="-2.7437" soft_upper_limit="2.7437" />
    <dynamics D="1" K="7000" damping="0.003" friction="0.2" mu_coulomb="0" mu_viscous="16" />
  </joint>
  
  <link name="fr3_link2">
    <visual name="fr3_link2_visual">
      <geometry>
        <cylinder radius="0.05" length="0.1" /></geometry>
    </visual>
    <collision name="fr3_link2_collision">
      <geometry>
        <mesh filename="../meshes/fr3/link2.stl" />
      </geometry>
    </collision>
    <inertial>
      <origin rpy="0 0 0" xyz="0.0031828864 -0.0743221644 0.0088146084" />
      <mass value="2.9355370338" />
      <inertia ixx="0.041938946257609425" ixy="0.00020257331521090626" ixz="0.004077784227179924" iyy="0.02514514885014724" iyz="-0.0042252158006570156" izz="0.06170214472888839" />
    </inertial>
  </link>
  <joint name="fr3_joint2" type="revolute">
    <origin rpy="-1.5696185407562486 0.008210958399695828 2.7813493976894585e-05" xyz="-0.00023636675490102925 -3.171408963301376e-05 3.041231128627539e-17" />
    <parent link="fr3_link1" />
    <child link="fr3_link2" />
    <axis xyz="0 0 1" />
    <limit effort="87.0" lower="-1.7837" upper="1.7837" velocity="2.62" />
    <safety_controller k_position="100.0" k_velocity="40.0" soft_lower_limit="-1.7837" soft_upper_limit="1.7837" />
    <dynamics D="1" K="7000" damping="0.003" friction="0.2" mu_coulomb="0" mu_viscous="16" />
  </joint>
  
  <link name="fr3_link3">
    <visual name="fr3_link3_visual">
      <geometry>
        <cylinder radius="0.05" length="0.1" /></geometry>
    </visual>
    <collision name="fr3_link3_collision">
      <geometry>
        <mesh filename="../meshes/fr3/link3.stl" />
      </geometry>
    </collision>
    <inertial>
      <origin rpy="0 0 0" xyz="0.0407015686 -0.0048200565 -0.0289730823" />
      <mass value="2.2449013699" />
      <inertia ixx="0.02410142547240885" ixy="0.002404694559042109" ixz="-0.002856269270114313" iyy="0.01974053266708178" iyz="-0.002104212683891874" izz="0.019044494482244823" />
    </inertial>
  </link>
  <joint name="fr3_joint3" type="revolute">
    <origin rpy="1.5684016448479587 -0.0017731455607090372 0.007309891705715417" xyz="0.002528557020503575 -0.31620648766036147 -1.4984159053003679e-05" />
    <parent link="fr3_link2" />
    <child link="fr3_link3" />
    <axis xyz="0 0 1" />
    <limit effort="87.0" lower="-2.9007" upper="2.9007" velocity="2.62" />
    <safety_controller k_position="100.0" k_velocity="40.0" soft_lower_limit="-2.9007" soft_upper_limit="2.9007" />
    <dynamics D="1" K="7000" damping="0.003" friction="0.2" mu_coulomb="0" mu_viscous="16" />
  </joint>
  
  <link name="fr3_link4">
    <visual name="fr3_link4_visual">
      <geometry>
        <cylinder radius="0.05" length="0.1" /></geometry>
    </visual>
    <collision name="fr3_link4_collision">
      <geometry>
        <mesh filename="../meshes/fr3/link4.stl" />
      </geometry>
    </collision>
    <inertial>
      <origin rpy="0 0 0" xyz="-0.0459100965 0.0630492960 -0.0085187868" />
      <mass value="2.6155955791" />
      <inertia ixx="0.03452998321913202" ixy="0.01322552265982813" ixz="0.01015142998484113" iyy="0.028881621933049058" iyz="-0.0009762833870704552" izz="0.04125471171146641" />
    </inertial>
  </link>
  <joint name="fr3_joint4" type="revolute">
    <origin rpy="1.5677326745390252 0.0013553051285632044 0.0018384954375648683" xyz="0.08220868988212866 0.0003194738824265976 0.00028586342227366306" />
    <parent link="fr3_link3" />
    <child link="fr3_link4" />
    <axis xyz="0 0 1" />
    <limit effort="87.0" lower="-3.0421" upper="-0.1518" velocity="2.62" />
    <safety_controller k_position="100.0" k_velocity="40.0" soft_lower_limit="-3.0421" soft_upper_limit="-0.1518" />
    <dynamics D="1" K="7000" damping="0.003" friction="0.2" mu_coulomb="0" mu_viscous="16" />
  </joint>
  
  <link name="fr3_link5">
    <visual name="fr3_link5_visual">
      <geometry>
        <cylinder radius="0.05" length="0.1" /></geometry>
    </visual>
    <collision name="fr3_link5_collision">
      <geometry>
        <mesh filename="../meshes/fr3/link5.stl" />
      </geometry>
    </collision>
    <inertial>
      <origin rpy="0 0 0" xyz="-0.0016039605 0.0292536262 -0.0972965990" />
      <mass value="2.3271207594" />
      <inertia ixx="0.051610278463662895" ixy="-0.005715173387783472" ixz="-0.0035673167625872135" iyy="0.04787729713371481" iyz="0.010673985108535986" izz="0.016423625579357254" />
    </inertial>
  </link>
  <joint name="fr3_joint5" type="revolute">
    <origin rpy="-1.571402921365619 0.0034937738473749817 -0.0010652956253299802" xyz="-0.08202406567204297 0.384714546232976 -0.0004781117970370225" />
    <parent link="fr3_link4" />
    <child link="fr3_link5" />
    <axis xyz="0 0 1" />
    <limit effort="12.0" lower="-2.8065" upper="2.8065" velocity="5.26" />
    <safety_controller k_position="100.0" k_velocity="40.0" soft_lower_limit="-2.8065" soft_upper_limit="2.8065" />
    <dynamics D="1" K="7000" damping="0.003" friction="0.2" mu_coulomb="0" mu_viscous="16" />
  </joint>
  
  <link name="fr3_link6">
    <visual name="fr3_link6_visual">
      <geometry>
        <cylinder radius="0.05" length="0.1" /></geometry>
    </visual>
    <collision name="fr3_link6_collision">
      <geometry>
        <mesh filename="../meshes/fr3/link6.stl" />
      </geometry>
    </collision>
    <inertial>
      <origin rpy="0 0 0" xyz="0.0597131221 -0.0410294666 -0.0101692726" />
      <mass value="1.8170376524" />
      <inertia ixx="0.005412333594383447" ixy="0.006193456360285834" ixz="0.0014219289306117652" iyy="0.014058329545509979" iyz="-0.0013140753741120031" izz="0.016080817924212554" />
    </inertial>
  </link>
  <joint name="fr3_joint6" type="revolute">
    <origin rpy="1.5665349784595053 -3.9408655076788224e-05 0.003531013141224253" xyz="0.0006847284750619545 0.00046201220443600126 0.000737471147760496" />
    <parent link="fr3_link5" />
    <child link="fr3_link6" />
    <axis xyz="0 0 1" />
    <limit effort="12.0" lower="0.5445" upper="4.5169" velocity="4.18" />
    <safety_controller k_position="100.0" k_velocity="40.0" soft_lower_limit="0.5445" soft_upper_limit="4.5169" />
    <dynamics D="1" K="7000" damping="0.003" friction="0.2" mu_coulomb="0" mu_viscous="16" />
  </joint>
  
  <link name="fr3_link7">
    <visual name="fr3_link7_visual">
      <geometry>
        <cylinder radius="0.05" length="0.1" /></geometry>
    </visual>
    <collision name="fr3_link7_collision">
      <geometry>
        <mesh filename="../meshes/fr3/link7.stl" />
      </geometry>
    </collision>
    <inertial>
      <origin rpy="0 0 0" xyz="0.0045225817 0.0086261921 -0.0161633251" />
      <mass value="0.6271432862" />
      <inertia ixx="0.00021092389150104718" ixy="-2.433299114461931e-05" ixz="4.564480393778983e-05" iyy="0.00017718568002411474" iyz="8.744070223226438e-05" izz="5.993190599659971e-05" />
    </inertial>
  </link>
  <joint name="fr3_joint7" type="revolute">
    <origin rpy="1.570923374062213 5.647094083122981e-06 8.985060067905656e-06" xyz="0.08786441088940533 -5.723066621044474e-05 -0.0003738464873402999" />
    <parent link="fr3_link6" />
    <child link="fr3_link7" />
    <axis xyz="0 0 1" />
    <limit effort="12.0" lower="-3.0159" upper="3.0159" velocity="5.26" />
    <safety_controller k_position="100.0" k_velocity="40.0" soft_lower_limit="-3.0159" soft_upper_limit="3.0159" />
    <dynamics D="1" K="7000" damping="0.003" friction="0.2" mu_coulomb="0" mu_viscous="16" />
  </joint>
  <link name="fr3_link8" />
  <joint name="fr3_joint8" type="fixed">
    <origin rpy="0 0 0" xyz="0 0 0.107" />
    <parent link="fr3_link7" />
    <child link="fr3_link8" />
  </joint>
  <joint name="fr3_hand_joint" type="fixed">
    <parent link="fr3_link8" />
    <child link="fr3_hand" />
    <origin rpy="0 0 -0.7853981633974483" xyz="0 0 0" />
  </joint>
  
  <link name="fr3_hand">
    <visual name="fr3_hand_visual">
      <geometry>
        <cylinder radius="0.05" length="0.1" /></geometry>
    </visual>
    <collision name="fr3_hand_collision">
      <geometry>
        <mesh filename="../meshes/fr3/hand.stl" />
      </geometry>
    </collision>
    <inertial>
      <origin rpy="0 0 0" xyz="-0.0000376 0.0119128 0.0207260" />
      <mass value="0.6544" />
      <inertia ixx="0.00186" ixy="0.0" ixz="0.0" iyy="0.0003" iyz="-2e-05" izz="0.00174" />
    </inertial>
  </link>
  
  <link name="fr3_hand_tcp" />
  <joint name="fr3_hand_tcp_joint" type="fixed">
    <origin rpy="0 0 0" xyz="0 0 0.1034" />
    <parent link="fr3_hand" />
    <child link="fr3_hand_tcp" />
  </joint>

  <link name="ball_link">
    <visual>
      <material name="red">
        <color rgba="1 0 0 1" />
      </material>
      <geometry>
        <sphere radius="0.005" />
      </geometry>
    </visual>
  </link>

  <joint name="ball_joint" type="fixed">

    <origin rpy="0.0 0.0 0.0" xyz="0.0005730360200059966 0.00017248661896517427 0.031751185050378196" />
    
    <parent link="fr3_hand_tcp" />
    <child link="ball_link" />
  </joint>

  <link name="fr3_leftfinger">
    <visual name="fr3_leftfinger_visual">
      <geometry>
        <cylinder radius="0.05" length="0.1" /></geometry>
    </visual>
    
    <collision>
      <origin rpy="0 0 0" xyz="0 18.5e-3 11e-3" />
      <geometry>
        <box size="22e-3 15e-3 20e-3" />
      </geometry>
    </collision>
    
    <collision>
      <origin rpy="0 0 0" xyz="0 6.8e-3 2.2e-3" />
      <geometry>
        <box size="22e-3 8.8e-3 3.8e-3" />
      </geometry>
    </collision>
    
    <collision>
      <origin rpy="0.5235987755982988 0 0" xyz="0 15.9e-3 28.35e-3" />
      <geometry>
        <box size="17.5e-3 7e-3 23.5e-3" />
      </geometry>
    </collision>
    
    <collision>
      <origin rpy="0 0 0" xyz="0 7.58e-3 45.25e-3" />
      <geometry>
        <box size="17.5e-3 15.2e-3 18.5e-3" />
      </geometry>
    </collision>
    <inertial>
      <origin rpy="0 0 0" xyz="0 0.0152850 0.0219675" />
      <mass value="0.0291" />
      <inertia ixx="8.49e-06" ixy="0.0" ixz="0.0" iyy="8.53e-06" iyz="-1.06e-06" izz="1.77e-06" />
    </inertial>
  </link>
  <link name="fr3_rightfinger">
    <visual name="fr3_rightfinger_visual">
      <origin rpy="0 0 0" xyz="0 0 0" />
      <geometry>
        <cylinder radius="0.05" length="0.1" /></geometry>
    </visual>
    
    <collision>
      <origin rpy="0 0 0" xyz="0 18.5e-3 11e-3" />
      <geometry>
        <box size="22e-3 15e-3 20e-3" />
      </geometry>
    </collision>
    
    <collision>
      <origin rpy="0 0 0" xyz="0 6.8e-3 2.2e-3" />
      <geometry>
        <box size="22e-3 8.8e-3 3.8e-3" />
      </geometry>
    </collision>
    
    <collision>
      <origin rpy="-0.5235987755982988 0 3.141592653589793" xyz="0 15.9e-3 28.35e-3" />
      <geometry>
        <box size="17.5e-3 7e-3 23.5e-3" />
      </geometry>
    </collision>
    
    <collision>
      <origin rpy="0 0 0" xyz="0 7.58e-3 45.25e-3" />
      <geometry>
        <box size="17.5e-3 15.2e-3 18.5e-3" />
      </geometry>
    </collision>
    <inertial>
      <origin rpy="0 0 0" xyz="0 0.0152850 0.0219675" />
      <mass value="0.0291" />
      <inertia ixx="8.49e-06" ixy="0.0" ixz="0.0" iyy="8.53e-06" iyz="-1.06e-06" izz="1.77e-06" />
    </inertial>
  </link>
  <joint name="fr3_finger_joint1" type="prismatic">
    <parent link="fr3_hand" />
    <child link="fr3_leftfinger" />
    <origin rpy="0 0 0" xyz="0 0 0.0584" />
    <axis xyz="0 1 0" />
    <limit effort="100" lower="0.0" upper="0.04" velocity="0.2" />
    <dynamics damping="0.3" />
  </joint>
  <joint name="fr3_finger_joint2" type="prismatic">
    <parent link="fr3_hand" />
    <child link="fr3_rightfinger" />
    <origin rpy="0 0 3.141592653589793" xyz="0 0 0.0584" />
    <axis xyz="0 1 0" />
    <limit effort="100" lower="0.0" upper="0.04" velocity="0.2" />
    <dynamics damping="0.3" />
  </joint>
</robot>