<robot name="panda">
  
  <link name="panda_link0">
    <visual>
      <geometry>
        <cylinder radius="0.05" length="0.1" /></geometry>
    </visual>
  </link>
  <link name="panda_link1">
    <visual>
      <geometry>
        <cylinder radius="0.05" length="0.1" /></geometry>
    </visual>
  </link>
  
  
  <joint name="panda_joint1" type="revolute">
    <origin rpy="-2.7467717976882093e-17 -8.522573595012005e-18 4.9950453830671253e-17" xyz="-3.6900698116198294e-17 -5.326870383549863e-17 0.3330000000000001" />
    <parent link="panda_link0" />
    <child link="panda_link1" />
    <axis xyz="0 0 1" />
    <limit effort="87.0" lower="-2.8973" upper="2.8973" velocity="2.175" />
    <safety_controller k_position="100.0" k_velocity="40.0" soft_lower_limit="-2.8973" soft_upper_limit="2.8973" />
  </joint>
  
  <link name="panda_link2">
    <visual>
      <geometry>
        <cylinder radius="0.05" length="0.1" /></geometry>
    </visual>
  </link>
  
  <joint name="panda_joint2" type="revolute">
    <origin rpy="-1.5725207437252064 0.0009372712466188919 -7.718083892607979e-08" xyz="-0.00017547829317862248 -0.0001889812802350597 5.596570925332979e-17" />
    <parent link="panda_link1" />
    <child link="panda_link2" />
    <axis xyz="0 0 1" />
    <limit effort="87.0" lower="-1.7628" upper="1.7628" velocity="2.175" />
    <safety_controller k_position="100.0" k_velocity="40.0" soft_lower_limit="-1.7628" soft_upper_limit="1.7628" />
  </joint>
  
  <link name="panda_link3">
    <visual>
      <geometry>
        <cylinder radius="0.05" length="0.1" /></geometry>
    </visual>
  </link>
  
  <joint name="panda_joint3" type="revolute">
    <origin rpy="1.5720348360853342 0.0003268619639532451 0.000832761921796104" xyz="0.0003319263936517206 -0.3161846150648603 -0.00018895982344008222" />
    <parent link="panda_link2" />
    <child link="panda_link3" />
    <axis xyz="0 0 1" />
    <limit effort="87.0" lower="-2.8973" upper="2.8973" velocity="2.175" />
    <safety_controller k_position="100.0" k_velocity="40.0" soft_lower_limit="-2.8973" soft_upper_limit="2.8973" />
  </joint>
  
  <link name="panda_link4">
    <visual>
      <geometry>
        <cylinder radius="0.05" length="0.1" /></geometry>
    </visual>
  </link>
  
  <joint name="panda_joint4" type="revolute">
    <origin rpy="1.573806792671812 0.011595459443393267 -0.00031396825539388174" xyz="0.082388649134067 -0.0001727688171565997 0.00018495336053392928" />
    <parent link="panda_link3" />
    <child link="panda_link4" />
    <axis xyz="0 0 1" />
    <limit effort="87.0" lower="-3.0718" upper="-0.0698" velocity="2.175" />
    <safety_controller k_position="100.0" k_velocity="40.0" soft_lower_limit="-3.0718" soft_upper_limit="-0.0698" />
  </joint>
  
  <link name="panda_link5">
    <visual>
      <geometry>
        <cylinder radius="0.05" length="0.1" /></geometry>
    </visual>
  </link>
  
  <joint name="panda_joint5" type="revolute">
    <origin rpy="-1.5699080415323887 0.005058296215925046 -0.010048610226775893" xyz="-0.07868753713895138 0.3849262637403298 0.0001729616179290193" />
    <parent link="panda_link4" />
    <child link="panda_link5" />
    <axis xyz="0 0 1" />
    <limit effort="12.0" lower="-2.8973" upper="2.8973" velocity="2.61" />
    <safety_controller k_position="100.0" k_velocity="40.0" soft_lower_limit="-2.8973" soft_upper_limit="2.8973" />
  </joint>
  
  <link name="panda_link6">
    <visual>
      <geometry>
        <cylinder radius="0.05" length="0.1" /></geometry>
    </visual>
  </link>
  
  <joint name="panda_joint6" type="revolute">
    <origin rpy="1.5706912155320047 -0.0005192359061647107 0.005049421685144415" xyz="0.0006950472168143404 1.019835198587951e-05 0.0009708585968305239" />
    <parent link="panda_link5" />
    <child link="panda_link6" />
    <axis xyz="0 0 1" />
    <limit effort="12.0" lower="-0.0175" upper="3.7525" velocity="2.61" />
    <safety_controller k_position="100.0" k_velocity="40.0" soft_lower_limit="-0.0175" soft_upper_limit="3.7525" />
  </joint>
  
  <link name="panda_link7">
    <visual>
      <geometry>
        <cylinder radius="0.05" length="0.1" /></geometry>
    </visual>
  </link>
  
  <joint name="panda_joint7" type="revolute">
    <origin rpy="1.5707623866443923 -1.4959906491989748e-07 0.0005198914565135234" xyz="0.09021311628110096 2.908913068697446e-06 -6.632305640823219e-06" />
    <parent link="panda_link6" />
    <child link="panda_link7" />
    <axis xyz="0 0 1" />
    <limit effort="12.0" lower="-2.8973" upper="2.8973" velocity="2.61" />
    <safety_controller k_position="100.0" k_velocity="40.0" soft_lower_limit="-2.8973" soft_upper_limit="2.8973" />
  </joint>
  <link name="panda_link8" />
  <joint name="panda_joint8" type="fixed">
    <origin rpy="0 0 0" xyz="0 0 0.107" />
    <parent link="panda_link7" />
    <child link="panda_link8" />
  </joint>
  <joint name="panda_hand_joint" type="fixed">
    <parent link="panda_link8" />
    <child link="panda_hand" />
    <origin rpy="0 0 -0.7853981633974483" xyz="0 0 0" />
  </joint>
  
  <link name="panda_hand">
    <visual>
      <geometry>
        <cylinder radius="0.05" length="0.1" /></geometry>
    </visual>
  </link>
  <link name="panda_hand_tcp" />
  <joint name="panda_hand_tcp_joint" type="fixed">
    <origin rpy="0 0 0" xyz="0 0 0.1034" />
    <parent link="panda_hand" />
    <child link="panda_hand_tcp" />
  </joint>
  <link name="ball_link">
    <visual>
      <material name="red">
        <color rgba="1 0 0 1" />
      </material>

      <geometry>
        <sphere radius="0.005" />
      </geometry>
    </visual>
  </link>

  <joint name="ball_joint" type="fixed">
    <origin rpy="0.0 0.0 0.0" xyz="0.0003822847472205753 -3.951824019036542e-05 0.0318669184198927" />
    <parent link="panda_hand_tcp" />
    <child link="ball_link" />
  </joint>
  <link name="panda_leftfinger">
    <visual>
      <geometry>
        <cylinder radius="0.05" length="0.1" /></geometry>
    </visual>
  </link>
  <link name="panda_rightfinger">
    <visual>
      <origin rpy="0 0 3.141592653589793" xyz="0 0 0" />
      <geometry>
        <cylinder radius="0.05" length="0.1" /></geometry>
    </visual>
  </link>

    <joint name="panda_finger_joint1" type="prismatic">
    <parent link="panda_hand" />
    <child link="panda_leftfinger" />
    <origin rpy="0 0 0" xyz="0 0 0.0584" />
    <axis xyz="0 1 0" />
    <limit effort="100" lower="0.0" upper="0.04" velocity="0.2" />
    <dynamics damping="0.3" />
  </joint>
  <joint name="panda_finger_joint2" type="prismatic">
    <parent link="panda_hand" />
    <child link="panda_rightfinger" />
    <origin rpy="0 0 0" xyz="0 0 0.0584" />
    <axis xyz="0 -1 0" />
    <limit effort="100" lower="0.0" upper="0.04" velocity="0.2" />
    <mimic joint="panda_finger_joint1" />
    <dynamics damping="0.3" />
  </joint>
</robot>