<robot name="panda">
  
  <link name="panda_link0">
    <visual>
      <geometry>
        <cylinder radius="0.05" length="0.1" /></geometry>
    </visual>
  </link>
  <link name="panda_link1">
    <visual>
      <geometry>
        <cylinder radius="0.05" length="0.1" /></geometry>
    </visual>
  </link>
  
  
  <joint name="panda_joint1" type="revolute">
    <origin rpy="-3.5462823226662726e-16 6.241945243187841e-16 2.4617764320157248e-15" xyz="-1.5170424558771883e-17 1.7237142468181242e-15 0.33299999999999913" />
    <parent link="panda_link0" />
    <child link="panda_link1" />
    <axis xyz="0 0 1" />
    <limit effort="87.0" lower="-2.8973" upper="2.8973" velocity="2.175" />
    <safety_controller k_position="100.0" k_velocity="40.0" soft_lower_limit="-2.8973" soft_upper_limit="2.8973" />
  </joint>
  
  <link name="panda_link2">
    <visual>
      <geometry>
        <cylinder radius="0.05" length="0.1" /></geometry>
    </visual>
  </link>
  
  <joint name="panda_joint2" type="revolute">
    <origin rpy="-1.5725193937716637 0.0008281734165854206 -5.234500694736838e-05" xyz="-0.00017832844093802582 -0.00018995018658545028 -9.064798466782615e-16" />
    <parent link="panda_link1" />
    <child link="panda_link2" />
    <axis xyz="0 0 1" />
    <limit effort="87.0" lower="-1.7628" upper="1.7628" velocity="2.175" />
    <safety_controller k_position="100.0" k_velocity="40.0" soft_lower_limit="-1.7628" soft_upper_limit="1.7628" />
  </joint>
  
  <link name="panda_link3">
    <visual>
      <geometry>
        <cylinder radius="0.05" length="0.1" /></geometry>
    </visual>
  </link>
  
  <joint name="panda_joint3" type="revolute">
    <origin rpy="1.572031856209447 0.0001102425608444286 0.0009382997032039687" xyz="0.0003668622975804948 -0.3162414296969163 -0.0001890003648581756" />
    <parent link="panda_link2" />
    <child link="panda_link3" />
    <axis xyz="0 0 1" />
    <limit effort="87.0" lower="-2.8973" upper="2.8973" velocity="2.175" />
    <safety_controller k_position="100.0" k_velocity="40.0" soft_lower_limit="-2.8973" soft_upper_limit="2.8973" />
  </joint>
  
  <link name="panda_link4">
    <visual>
      <geometry>
        <cylinder radius="0.05" length="0.1" /></geometry>
    </visual>
  </link>
  
  <joint name="panda_joint4" type="revolute">
    <origin rpy="1.5739111663380858 0.012732371030732315 -0.00034856840610989344" xyz="0.08237725734283452 8.491581863865304e-05 0.00011863291016775383" />
    <parent link="panda_link3" />
    <child link="panda_link4" />
    <axis xyz="0 0 1" />
    <limit effort="87.0" lower="-3.0718" upper="-0.0698" velocity="2.175" />
    <safety_controller k_position="100.0" k_velocity="40.0" soft_lower_limit="-3.0718" soft_upper_limit="-0.0698" />
  </joint>
  
  <link name="panda_link5">
    <visual>
      <geometry>
        <cylinder radius="0.05" length="0.1" /></geometry>
    </visual>
  </link>
  
  <joint name="panda_joint5" type="revolute">
    <origin rpy="-1.5696951293557795 0.005066290903111269 -0.00888355665300759" xyz="-0.07915514246318092 0.38336862640785524 0.0005285307438166519" />
    <parent link="panda_link4" />
    <child link="panda_link5" />
    <axis xyz="0 0 1" />
    <limit effort="12.0" lower="-2.8973" upper="2.8973" velocity="2.61" />
    <safety_controller k_position="100.0" k_velocity="40.0" soft_lower_limit="-2.8973" soft_upper_limit="2.8973" />
  </joint>
  
  <link name="panda_link6">
    <visual>
      <geometry>
        <cylinder radius="0.05" length="0.1" /></geometry>
    </visual>
  </link>
  
  <joint name="panda_joint6" type="revolute">
    <origin rpy="1.5706270263968867 -0.00079995683568176 0.00506514166180295" xyz="0.0006932294955304499 2.2377305875545506e-05 0.002436321248351335" />
    <parent link="panda_link5" />
    <child link="panda_link6" />
    <axis xyz="0 0 1" />
    <limit effort="12.0" lower="-0.0175" upper="3.7525" velocity="2.61" />
    <safety_controller k_position="100.0" k_velocity="40.0" soft_lower_limit="-0.0175" soft_upper_limit="3.7525" />
  </joint>
  
  <link name="panda_link7">
    <visual>
      <geometry>
        <cylinder radius="0.05" length="0.1" /></geometry>
    </visual>
  </link>
  
  <joint name="panda_joint7" type="revolute">
    <origin rpy="1.5706666020789413 -0.00010919931774771034 0.0010488513658257355" xyz="0.0900167039252617 0.00038247028193025235 -2.358238969640063e-06" />
    <parent link="panda_link6" />
    <child link="panda_link7" />
    <axis xyz="0 0 1" />
    <limit effort="12.0" lower="-2.8973" upper="2.8973" velocity="2.61" />
    <safety_controller k_position="100.0" k_velocity="40.0" soft_lower_limit="-2.8973" soft_upper_limit="2.8973" />
  </joint>
  <link name="panda_link8" />
  <joint name="panda_joint8" type="fixed">
    <origin rpy="0 0 0" xyz="0 0 0.107" />
    <parent link="panda_link7" />
    <child link="panda_link8" />
  </joint>
  <joint name="panda_hand_joint" type="fixed">
    <parent link="panda_link8" />
    <child link="panda_hand" />
    <origin rpy="0 0 -0.7853981633974483" xyz="0 0 0" />
  </joint>
  
  <link name="panda_hand">
    <visual>
      <geometry>
        <cylinder radius="0.05" length="0.1" /></geometry>
    </visual>
  </link>
  <link name="panda_hand_tcp" />
  <joint name="panda_hand_tcp_joint" type="fixed">
    <origin rpy="0 0 0" xyz="0 0 0.1034" />
    <parent link="panda_hand" />
    <child link="panda_hand_tcp" />
  </joint>
  <link name="ball_link">
    <visual>
      <material name="red">
        <color rgba="1 0 0 1" />
      </material>

      <geometry>
        <sphere radius="0.005" />
      </geometry>
    </visual>
  </link>

  <joint name="ball_joint" type="fixed">
    <origin rpy="0.0 0.0 0.0" xyz="0.0003831901924278027 -3.994204598073655e-05 0.032264980220807996" />
    <parent link="panda_hand_tcp" />
    <child link="ball_link" />
  </joint>
  <link name="panda_leftfinger">
    <visual>
      <geometry>
        <cylinder radius="0.05" length="0.1" /></geometry>
    </visual>
  </link>
  <link name="panda_rightfinger">
    <visual>
      <origin rpy="0 0 3.141592653589793" xyz="0 0 0" />
      <geometry>
        <cylinder radius="0.05" length="0.1" /></geometry>
    </visual>
  </link>

    <joint name="panda_finger_joint1" type="prismatic">
    <parent link="panda_hand" />
    <child link="panda_leftfinger" />
    <origin rpy="0 0 0" xyz="0 0 0.0584" />
    <axis xyz="0 1 0" />
    <limit effort="100" lower="0.0" upper="0.04" velocity="0.2" />
    <dynamics damping="0.3" />
  </joint>
  <joint name="panda_finger_joint2" type="prismatic">
    <parent link="panda_hand" />
    <child link="panda_rightfinger" />
    <origin rpy="0 0 0" xyz="0 0 0.0584" />
    <axis xyz="0 -1 0" />
    <limit effort="100" lower="0.0" upper="0.04" velocity="0.2" />
    <mimic joint="panda_finger_joint1" />
    <dynamics damping="0.3" />
  </joint>
</robot>