<robot name="panda">
  
  <link name="panda_link0">
    <visual>
      <geometry>
        <cylinder radius="0.05" length="0.1" /></geometry>
    </visual>
  </link>
  <link name="panda_link1">
    <visual>
      <geometry>
        <cylinder radius="0.05" length="0.1" /></geometry>
    </visual>
  </link>
  
  
  <joint name="panda_joint1" type="revolute">
    <origin rpy="-3.63592163733799e-15 4.986002674718797e-16 -5.36094896076785e-15" xyz="-9.32035983533236e-16 -7.926103829464726e-15 0.3330000000000004" />
    <parent link="panda_link0" />
    <child link="panda_link1" />
    <axis xyz="0 0 1" />
    <limit effort="87.0" lower="-2.8973" upper="2.8973" velocity="2.175" />
    <safety_controller k_position="100.0" k_velocity="40.0" soft_lower_limit="-2.8973" soft_upper_limit="2.8973" />
  </joint>
  
  <link name="panda_link2">
    <visual>
      <geometry>
        <cylinder radius="0.05" length="0.1" /></geometry>
    </visual>
  </link>
  
  <joint name="panda_joint2" type="revolute">
    <origin rpy="-1.5734437829212131 -0.002040609888460357 -0.0013973132782436018" xyz="-0.0008950137411981567 -0.00016990041113440442 3.5312187434920313e-16" />
    <parent link="panda_link1" />
    <child link="panda_link2" />
    <axis xyz="0 0 1" />
    <limit effort="87.0" lower="-1.7628" upper="1.7628" velocity="2.175" />
    <safety_controller k_position="100.0" k_velocity="40.0" soft_lower_limit="-1.7628" soft_upper_limit="1.7628" />
  </joint>
  
  <link name="panda_link3">
    <visual>
      <geometry>
        <cylinder radius="0.05" length="0.1" /></geometry>
    </visual>
  </link>
  
  <joint name="panda_joint3" type="revolute">
    <origin rpy="1.5732627019041465 -0.003449493535660277 0.003004797732318423" xyz="0.001306309119596687 -0.32331179384358055 -5.278826163674028e-05" />
    <parent link="panda_link2" />
    <child link="panda_link3" />
    <axis xyz="0 0 1" />
    <limit effort="87.0" lower="-2.8973" upper="2.8973" velocity="2.175" />
    <safety_controller k_position="100.0" k_velocity="40.0" soft_lower_limit="-2.8973" soft_upper_limit="2.8973" />
  </joint>
  
  <link name="panda_link4">
    <visual>
      <geometry>
        <cylinder radius="0.05" length="0.1" /></geometry>
    </visual>
  </link>
  
  <joint name="panda_joint4" type="revolute">
    <origin rpy="1.5776001970143645 0.045155667254955206 -0.0025404157981077477" xyz="0.08781270128972815 0.0052140180045737936 0.004627456087405854" />
    <parent link="panda_link3" />
    <child link="panda_link4" />
    <axis xyz="0 0 1" />
    <limit effort="87.0" lower="-3.0718" upper="-0.0698" velocity="2.175" />
    <safety_controller k_position="100.0" k_velocity="40.0" soft_lower_limit="-3.0718" soft_upper_limit="-0.0698" />
  </joint>
  
  <link name="panda_link5">
    <visual>
      <geometry>
        <cylinder radius="0.05" length="0.1" /></geometry>
    </visual>
  </link>
  
  <joint name="panda_joint5" type="revolute">
    <origin rpy="-1.5670882472441663 0.005117459710277482 0.005170577617733388" xyz="-0.08747454056142297 0.3547160137678064 0.0067630074804234394" />
    <parent link="panda_link4" />
    <child link="panda_link5" />
    <axis xyz="0 0 1" />
    <limit effort="12.0" lower="-2.8973" upper="2.8973" velocity="2.61" />
    <safety_controller k_position="100.0" k_velocity="40.0" soft_lower_limit="-2.8973" soft_upper_limit="2.8973" />
  </joint>
  
  <link name="panda_link6">
    <visual>
      <geometry>
        <cylinder radius="0.05" length="0.1" /></geometry>
    </visual>
  </link>
  
  <joint name="panda_joint6" type="revolute">
    <origin rpy="1.5732891692191167 -0.0064055899057603284 0.005424463815580742" xyz="-0.0013237021742340538 0.0019468624666521633 0.03447181793160154" />
    <parent link="panda_link5" />
    <child link="panda_link6" />
    <axis xyz="0 0 1" />
    <limit effort="12.0" lower="-0.0175" upper="3.7525" velocity="2.61" />
    <safety_controller k_position="100.0" k_velocity="40.0" soft_lower_limit="-0.0175" soft_upper_limit="3.7525" />
  </joint>
  
  <link name="panda_link7">
    <visual>
      <geometry>
        <cylinder radius="0.05" length="0.1" /></geometry>
    </visual>
  </link>
  
  <joint name="panda_joint7" type="revolute">
    <origin rpy="1.569554097481019 -0.0024356304521552254 0.013892569879178794" xyz="0.08713730409643586 -0.000993536863307715 0.0015690418361028807" />
    <parent link="panda_link6" />
    <child link="panda_link7" />
    <axis xyz="0 0 1" />
    <limit effort="12.0" lower="-2.8973" upper="2.8973" velocity="2.61" />
    <safety_controller k_position="100.0" k_velocity="40.0" soft_lower_limit="-2.8973" soft_upper_limit="2.8973" />
  </joint>
  <link name="panda_link8" />
  <joint name="panda_joint8" type="fixed">
    <origin rpy="0 0 0" xyz="0 0 0.107" />
    <parent link="panda_link7" />
    <child link="panda_link8" />
  </joint>
  <joint name="panda_hand_joint" type="fixed">
    <parent link="panda_link8" />
    <child link="panda_hand" />
    <origin rpy="0 0 -0.7853981633974483" xyz="0 0 0" />
  </joint>
  
  <link name="panda_hand">
    <visual>
      <geometry>
        <cylinder radius="0.05" length="0.1" /></geometry>
    </visual>
  </link>
  <link name="panda_hand_tcp" />
  <joint name="panda_hand_tcp_joint" type="fixed">
    <origin rpy="0 0 0" xyz="0 0 0.1034" />
    <parent link="panda_hand" />
    <child link="panda_hand_tcp" />
  </joint>
  <link name="ball_link">
    <visual>
      <material name="red">
        <color rgba="1 0 0 1" />
      </material>

      <geometry>
        <sphere radius="0.005" />
      </geometry>
    </visual>
  </link>

  <joint name="ball_joint" type="fixed">
    <origin rpy="0.0 0.0 0.0" xyz="7.602896568335599e-05 -0.00016399801535301248 0.037561202187216765" />
    <parent link="panda_hand_tcp" />
    <child link="ball_link" />
  </joint>
  <link name="panda_leftfinger">
    <visual>
      <geometry>
        <cylinder radius="0.05" length="0.1" /></geometry>
    </visual>
  </link>
  <link name="panda_rightfinger">
    <visual>
      <origin rpy="0 0 3.141592653589793" xyz="0 0 0" />
      <geometry>
        <cylinder radius="0.05" length="0.1" /></geometry>
    </visual>
  </link>

    <joint name="panda_finger_joint1" type="prismatic">
    <parent link="panda_hand" />
    <child link="panda_leftfinger" />
    <origin rpy="0 0 0" xyz="0 0 0.0584" />
    <axis xyz="0 1 0" />
    <limit effort="100" lower="0.0" upper="0.04" velocity="0.2" />
    <dynamics damping="0.3" />
  </joint>
  <joint name="panda_finger_joint2" type="prismatic">
    <parent link="panda_hand" />
    <child link="panda_rightfinger" />
    <origin rpy="0 0 0" xyz="0 0 0.0584" />
    <axis xyz="0 -1 0" />
    <limit effort="100" lower="0.0" upper="0.04" velocity="0.2" />
    <mimic joint="panda_finger_joint1" />
    <dynamics damping="0.3" />
  </joint>
</robot>